<?xml version="1.0"?>
<robot name="cherry_bot">
  
  <link name="base"/>

  <joint name="fixed" type="fixed">
    <parent link="base"/>
    <child link="link_0"/>
  </joint>


  <link name="link_0">
    <visual>
      <geometry>
        <cylinder length="0.6" radius="0.2"/>
      </geometry>
    </visual>

    <collision>
      <geometry>
        <cylinder length="0.6" radius="0.2"/>
      </geometry>
    </collision>

    <inertial>
      <mass value="10"/>
      <inertia ixx="0.4" ixy="0.0" ixz="0.0" iyy="0.4" iyz="0.0" izz="0.2"/>
    </inertial>
  </link>

  <joint name="joint1" type="revolute">
    <axis xyz="1 0 0"/>
    <limit effort="30.0" lower="-1.570" upper="1.570" velocity="0.5"/>
    <parent link="link_0"/>
    <child link="link_1"/>
    <origin xyz="0 0 0.3"/>
  </joint>


  <link name="link_1">
    <visual>
      <geometry>
        <cylinder length="0.6" radius="0.2"/>
      </geometry>
      <origin rpy="0 0 0" xyz="0 0 0.3"/>
    </visual>

    <collision>
      <geometry>
        <cylinder length="0.6" radius="0.2"/>
      </geometry>
      <origin rpy="0 0 0" xyz="0 0 0.3"/>
    </collision>

    <inertial>
      <mass value="10"/>
      <inertia ixx="0.4" ixy="0.0" ixz="0.0" iyy="0.4" iyz="0.0" izz="0.2"/>
    </inertial>
  </link>

  <joint name="joint2" type="revolute">
    <axis xyz="1 0 0"/>
    <limit effort="30.0" lower="-1.570" upper="1.570" velocity="0.5"/>
    <parent link="link_1"/>
    <child link="link_2"/>
    <origin xyz="0 0 0.6"/>
  </joint>

  <link name="link_2">
    <visual>
      <geometry>
        <cylinder length="0.6" radius="0.2"/>
      </geometry>
      <origin rpy="0 0 0" xyz="0 0 0.3"/>
    </visual>

    <collision>
      <geometry>
        <cylinder length="0.6" radius="0.2"/>
      </geometry>
      <origin rpy="0 0 0" xyz="0 0 0.3"/>
    </collision>

    <inertial>
      <mass value="10"/>
      <inertia ixx="0.4" ixy="0.0" ixz="0.0" iyy="0.4" iyz="0.0" izz="0.2"/>
    </inertial>
  </link>

</robot>